
# 异常

异常是程序运行中允许出现的，能被容忍的错误

## 处理异常


### 异常分类

`Throwable` 有两个子类

- `Error` 系统级别异常。通常是 `Java` 运行时内部错误或资源耗尽错误，这种错误通常都是致命的。但 抛出 Error 后，Java 进程也不一定会被自动关闭
- `Exception` 应用级别异常。分两大类
  - `RunTimeException` 运行时异常。通常出现异常的原因是代码的问题。比如，空指针，数组下标越界，类型转换错误
  - 其他异常。通常是程序代码没有问题，是运行时，环境复杂造成的异常。比如打开一个不存在的文件，进行网络通信时突然断网等

> “如果出现 **RuntimeException** 异常，那么就一定是你的问题“ 是一条相当有道理的规则

`Error` 和 `RunTimeException` 是非受查异常

其他异常是受查异常

编译器为受查异常提供**异常处理器（try-catch块）**


### 声明受检查的异常

如果方法可能抛出一些受查异常，应该在方法定义处声明这些异常

```java
public void functionName() throws AException, BException
```

不应该声明非受查异常（`Error` 的子类和 `RunnTimeException` 及其子类）


**子类重写父类方法时如何声明异常列表**

如果在子类中覆盖了超类的一个方法， 子类方法中声明的受查异常不能比超类方法中声明的异常更通用 （也就是说， 子类方法中可以抛出更特定的异常， 或者根本不抛出任何异常）

原因：父类引用的实际类型可能是子类对象，而父类引用调用方法只能抛出父类方法中声明的异常。不管对象的实际类型是什么都要保证异常能被捕捉，所以子类需要配合父类


### 抛出异常

```java
// throw + 异常对象
throw exception;
```


### 创建异常类

创建一个 `Exception` 或其子类的子类


## 捕捉异常


### 异常处理器

**如果一个异常没有被任何一个地方进行捕获，那当前线程就会终止执行**，如果 main 抛出了异常，那但当前进程就会终止


异常处理器的构成

```java
try {
    ...
} catch(AException a) {
    ...
} catch(BException b) {
    ...
}
```

- 异常链中从上到下，`AException`<`Bexception>` 或 `AException` 和 `Bexception` 毫无关系（异常的类型越来越通用或毫无关系）
- `catch` 列表中的异常变量隐含为 `final` 变量
- 抛出异常后，跳过 `try` 块中当前语句下的所有语句


### 再次抛出异常

在异常处理器中能再次抛出异常

这样做的目的通常是改变异常的类型


**异常包装技术**

```java
catch(SQLException e) {
    Throwable se = new ServletException ("database error");
	se.initCause(e);
	throw se;
}
```

改变异常的类型并再次抛出，当捕捉到异常时，能这样获取原始的异常

```java
Throwable e = se.getCause();
```


### finally 块

`finally` 块的格式（`catch` 块不是必须的）

```java
try {
    ...
} catch (Exception e){
    ...
} finally {
    ...
}
```

在执行 `try-catch-finally` 块中执行 `return` 前会执行 `finally` 里的语句

有关 `finally` 块的详细说明见 JVM，例如

- 在 `finally` 块中执行 `return`
- 在 `finally` 块中修改返回值，但无论在 finally 代码块中是否修改返回值，返回值都不会改变


## 带资源的 try 块


带资源的 `try` 语句（ `try-with-resources` ) 的最简形式

```java
// 列表中的资源用';'分割
try (Resource resource1 = ...; Resource resource2 = ...) {
	// work with resource
}
```

如果 `Resource` 实现了 `AutoCloseable `接口，在代码退出 `try` 块后会执行 `resource.close()` 方法（ `AutoCloseable ` 接口的方法）


> 如果 try 块抛出一个异常， 而且 close 方法也抛出一个异常，这就会带来一个难题。带资源的 try 语句可以很好地处理这种情况。原来的异常会重新抛出，而 close方法抛出的异常会“被抑制”，这些异常将自动捕获，并由 addSuppressed 方法增加到原来的异常。 如果对这些异常感兴趣， 可以调用 getSuppressed 方法，它会得到从 close 方法抛出并被抑制的异常列表


补充：带资源的 try 语句自身也可以有 catch 子句和一个 finally 子句。 这些子句会**在关闭资源之后**执行。

[[../../021 - 离线网页备份文件夹/在java中如何处理finally块中的抛出异常以及finally和return的一些细节_finally里面可以抛出异常吗.html|finally块中使用return会抑制异常的冒泡传输和finally中抛异常应该如何处理]]


## 获取堆栈轨迹

方式一

```java
Throwable t = new ThrowableO ;
StackTraceElement[] frames = t.getStackTrace();
for (StackTraceElement frame : frames)
	// analyze frame
```

方式二

```java
Map<Thread, StackTraceElement[]> map = Thread.getAllStackTraces();
for (Thread t : map. keySet ()) {
    StackTraceElement[] frames = map.get(t);
    // analyze frames
}
```

`StackTraceElement` 类含有能够获得文件名和当前执行的代码行号的方法，还含有能够获得类名和方法名的方法


# 断言

> 测试程序时用 `System.out.println` 输出数据实现测试的策略执行时既费时又需要频繁去除（测试完成后需要手动去掉这些测试代码）
>
> 断言能选择性地启用测试以及打印测试信息


## 断言的概念和表达式

如果断言错误，抛出 `AssertError` 错误

如果断言条件后有表达式，表达式将作为错误信息传递到 `AssertError` 中

```java
assert 条件;

assert 条件 : 表达式;
```

`AssertError` 是非受查异常，断言出现的错误是不被期望的，不能被容忍的，一定需要被避免出现的错误

和 `Exception` 不同，断言错误在程序上线后是一定不能出现的


## 启用和禁用断言

默认断言被禁用。通过 `JVM` 参数控制断言的启用和禁用

```shell
# 启用所有断言
-ea
# 启用指定类或包下所有类的断言
-ea:OneClass -ea:com.example...

# 禁用断言
-da
# 禁用指定类或包下所有类的断言
-da:OneClass -ea:com.example...
```


## 断言实现参数检查

```java
int i = 3;

assert
```


## 使用断言的时机

- 断言用于开发和测试阶段
- 如果明确要求某个方法的参数一定符合某种规范，否则程序直接崩掉。这些情况下使用断言对参数进行检查


**断言和异常的使用场景**

- 异常用于处理已知的可能出现问题的地方，是项目上线后。例如，根据 `username` 从 `db` 获取数据，结果数据为空，应该抛类似 `UserNotFoundException`
- 断言用于处理预期中绝对不会出现的错误。例如某个方法的参数必须为正数，且正常情况下接收到的参数都是正数。




**拓展**

用 `-verbose` 标志启动 `Java` 虚拟机，有时候，这种方法有助于诊断由于类路径引发的问题 #有待了解 


# 抽空整理一下 JDK 内置的常用异常

包括受检的和未受检的 #有待了解 